Workbook
Name AREAS: BD!$H$4:$H$8
Name AUTORIZADO: BD!$G$4:$G$8
Name ELABORADO: BD!$G$4:$G$8
Name RESPONSABLE: BD!$G$4:$G$8

Sheet PORTADA
D2: Industrias Metálicas del centro S.A. de C.V.
B9: SISTEMA DE GESTIÓN DE MANTENIMIENTO
B12: Preventivo · Correctivo · Control de Costos · KPIs
B16: Empresa: | C16: =CONFIG!B2 -> Industrias Metálicas del Centro S.A. de C.V.
B17: Planta / Sede: | C17: =CONFIG!B3 -> Planta Puebla — Nave de Producción
B18: Responsable: | C18: =CONFIG!B4 -> Ing. Carlos Martínez López
B19: Año fiscal: | C19: =CONFIG!B5 -> 2025
B20: Versión: | C20: 1.0
B21: Última actualización: | C21: =TEXT(TODAY(),"DD/MM/YYYY") -> 20/05/YYYY
B24: 📋 PROGRAMA | E24: Control semanal de actividades PM/CM
B25: 🏭 MÁQUINAS | E25: Registro y ficha técnica de equipos
B26: 🔧 MANTENIMIENTOS | E26: Historial de intervenciones PM y CM
B27: 📦 ALMACÉN | E27: Inventario de repuestos y materiales
B28: 💰 COSTOS | E28: Presupuesto y análisis de costos
B29: 📄 COTIZACIÓN | E29: Generación de cotizaciones de mantenimiento
B30: 📊 DASHBOARD | E30: Indicadores KPI y semáforos
B31: 📑 INFORME | E31: Reporte por equipo individual
B33: CONFIDENCIAL — USO INTERNO

Sheet DASHBOARD
A1: DASHBOARD — CONTROL DE MANTENIMIENTO PREVENTIVO Y CORRECTIVO
A2: Actualización automática al modificar hoja PROGRAMA o MANTENIMIENTOS | Metas: Cumplimiento ≥ 90% | Efectividad ≥ 80%
A3: PROGRAMADOS (PR) | C3: EJECUTADOS (E) | E3: REPROGRAMADOS (R) | G3: NO EJECUTADOS (N) | I3: PENDIENTES (P) | K3: % CUMPLIMIENTO | M3: % EFECTIVIDAD | O3: COSTO TOTAL
A4: =COUNTA(PROGRAMA!H10:H5000) -> 40 | C4: =SUM(PROGRAMA!I10:I5000) -> 32 | E4: =SUM(PROGRAMA!J10:J5000) -> 4 | G4: =SUM(PROGRAMA!K10:K5000) -> 0 | I4: =SUM(PROGRAMA!L10:L5000) -> 4 | K4: =IFERROR(SUM(PROGRAMA!I10:I5000)/COUNTA(PROGRAMA!H10:H5000),0) -> 0.8 | M4: =IFERROR((SUM(PROGRAMA!I10:I5000)+SUM(PROGRAMA!J10:J5000))/(COUNTA(PROGRAMA!H10:H5000)-SUM(PROGRAMA!K10:K5000)),0) -> 0.9 | O4: =SUM(MANTENIMIENTOS!L11:L5000)+SUM(MANTENIMIENTOS!M11:M5000) -> 42550
A7: SEMÁFORO CUMPLIMIENTO | E7: SEMÁFORO EFECTIVIDAD
A8: =IF(IFERROR(SUM(PROGRAMA!I10:I5000)/COUNTA(PROGRAMA!H10:H5000),0)>=0.9,"✅ CUMPLIMIENTO ÓPTIMO ≥ 90%",IF(IFERROR(SUM(PROGRAMA!I10:I5000)/COUNTA(PROGRAMA!H10:H5000),0)>=0.75,"⚠ CUMPLIMIENTO REGULAR 75-89%","❌ CUMPLIMIENTO CRÍTICO < 75%")) -> ⚠ CUMPLIMIENTO REGULAR 75-89% | E8: =IF(IFERROR((SUM(PROGRAMA!I10:I5000)+SUM(PROGRAMA!J10:J5000))/(COUNTA(PROGRAMA!H10:H5000)-SUM(PROGRAMA!K10:K5000)),0)>=0.8,"✅ EFECTIVIDAD ÓPTIMA ≥ 80%","⚠ EFECTIVIDAD POR DEBAJO DE META") -> ✅ EFECTIVIDAD ÓPTIMA ≥ 80%
A10: RESUMEN POR EQUIPO
A11: CÓDIGO | B11: EQUIPO | C11: PR | D11: E | E11: R | F11: N | G11: P | H11: % CUMPLIM. | I11: % EFECTIVID. | J11: SEMÁFORO | K11: PUNTAJE | L11: COSTO TOTAL
A12: M-001 | B12: Torno CNC TL-500 | C12: =COUNTIF(PROGRAMA!B10:B5000,A12) -> 4 | D12: =SUMIF(PROGRAMA!B10:B5000,A12,PROGRAMA!I10:I5000) -> 4 | E12: =SUMIF(PROGRAMA!B10:B5000,A12,PROGRAMA!J10:J5000) -> 0 | F12: =SUMIF(PROGRAMA!B10:B5000,A12,PROGRAMA!K10:K5000) -> 0 | G12: =SUMIF(PROGRAMA!B10:B5000,A12,PROGRAMA!L10:L5000) -> 0 | H12: =IFERROR(D12/C12,0) -> 1 | I12: =IFERROR((D12+E12)/(C12-F12),0) -> 1 | J12: =IF(H12>=0.9,"✅ Óptimo",IF(H12>=0.75,"⚠ Regular","❌ Crítico")) -> ✅ Óptimo | K12: =H12*0.6+I12*0.4 -> 1 | L12: =SUMIFS(MANTENIMIENTOS!L:L,MANTENIMIENTOS!N:N,B12)+SUMIFS(MANTENIMIENTOS!M:M,MANTENIMIENTOS!N:N,B12) -> 4810
A13: M-002 | B13: Fresadora Vertical FV-300 | C13: =COUNTIF(PROGRAMA!B10:B5000,A13) -> 4 | D13: =SUMIF(PROGRAMA!B10:B5000,A13,PROGRAMA!I10:I5000) -> 3 | E13: =SUMIF(PROGRAMA!B10:B5000,A13,PROGRAMA!J10:J5000) -> 1 | F13: =SUMIF(PROGRAMA!B10:B5000,A13,PROGRAMA!K10:K5000) -> 0 | G13: =SUMIF(PROGRAMA!B10:B5000,A13,PROGRAMA!L10:L5000) -> 0 | H13: =IFERROR(D13/C13,0) -> 0.75 | I13: =IFERROR((D13+E13)/(C13-F13),0) -> 1 | J13: =IF(H13>=0.9,"✅ Óptimo",IF(H13>=0.75,"⚠ Regular","❌ Crítico")) -> ⚠ Regular | K13: =H13*0.6+I13*0.4 -> 0.85 | L13: =SUMIFS(MANTENIMIENTOS!L:L,MANTENIMIENTOS!N:N,B13)+SUMIFS(MANTENIMIENTOS!M:M,MANTENIMIENTOS!N:N,B13) -> 6690
A14: M-003 | B14: Taladro Radial TR-200 | C14: =COUNTIF(PROGRAMA!B10:B5000,A14) -> 4 | D14: =SUMIF(PROGRAMA!B10:B5000,A14,PROGRAMA!I10:I5000) -> 3 | E14: =SUMIF(PROGRAMA!B10:B5000,A14,PROGRAMA!J10:J5000) -> 0 | F14: =SUMIF(PROGRAMA!B10:B5000,A14,PROGRAMA!K10:K5000) -> 0 | G14: =SUMIF(PROGRAMA!B10:B5000,A14,PROGRAMA!L10:L5000) -> 1 | H14: =IFERROR(D14/C14,0) -> 0.75 | I14: =IFERROR((D14+E14)/(C14-F14),0) -> 0.75 | J14: =IF(H14>=0.9,"✅ Óptimo",IF(H14>=0.75,"⚠ Regular","❌ Crítico")) -> ⚠ Regular | K14: =H14*0.6+I14*0.4 -> 0.75 | L14: =SUMIFS(MANTENIMIENTOS!L:L,MANTENIMIENTOS!N:N,B14)+SUMIFS(MANTENIMIENTOS!M:M,MANTENIMIENTOS!N:N,B14) -> 4510
A15: M-004 | B15: Soldadora MIG SW-450 | C15: =COUNTIF(PROGRAMA!B10:B5000,A15) -> 4 | D15: =SUMIF(PROGRAMA!B10:B5000,A15,PROGRAMA!I10:I5000) -> 2 | E15: =SUMIF(PROGRAMA!B10:B5000,A15,PROGRAMA!J10:J5000) -> 1 | F15: =SUMIF(PROGRAMA!B10:B5000,A15,PROGRAMA!K10:K5000) -> 0 | G15: =SUMIF(PROGRAMA!B10:B5000,A15,PROGRAMA!L10:L5000) -> 1 | H15: =IFERROR(D15/C15,0) -> 0.5 | I15: =IFERROR((D15+E15)/(C15-F15),0) -> 0.75 | J15: =IF(H15>=0.9,"✅ Óptimo",IF(H15>=0.75,"⚠ Regular","❌ Crítico")) -> ❌ Crítico | K15: =H15*0.6+I15*0.4 -> 0.6 | L15: =SUMIFS(MANTENIMIENTOS!L:L,MANTENIMIENTOS!N:N,B15)+SUMIFS(MANTENIMIENTOS!M:M,MANTENIMIENTOS!N:N,B15) -> 4720
A16: M-005 | B16: Compresor Industrial CI-75 | C16: =COUNTIF(PROGRAMA!B10:B5000,A16) -> 4 | D16: =SUMIF(PROGRAMA!B10:B5000,A16,PROGRAMA!I10:I5000) -> 4 | E16: =SUMIF(PROGRAMA!B10:B5000,A16,PROGRAMA!J10:J5000) -> 0 | F16: =SUMIF(PROGRAMA!B10:B5000,A16,PROGRAMA!K10:K5000) -> 0 | G16: =SUMIF(PROGRAMA!B10:B5000,A16,PROGRAMA!L10:L5000) -> 0 | H16: =IFERROR(D16/C16,0) -> 1 | I16: =IFERROR((D16+E16)/(C16-F16),0) -> 1 | J16: =IF(H16>=0.9,"✅ Óptimo",IF(H16>=0.75,"⚠ Regular","❌ Crítico")) -> ✅ Óptimo | K16: =H16*0.6+I16*0.4 -> 1 | L16: =SUMIFS(MANTENIMIENTOS!L:L,MANTENIMIENTOS!N:N,B16)+SUMIFS(MANTENIMIENTOS!M:M,MANTENIMIENTOS!N:N,B16) -> 2460
A17: M-006 | B17: Prensa Hidráulica PH-100 | C17: =COUNTIF(PROGRAMA!B10:B5000,A17) -> 4 | D17: =SUMIF(PROGRAMA!B10:B5000,A17,PROGRAMA!I10:I5000) -> 4 | E17: =SUMIF(PROGRAMA!B10:B5000,A17,PROGRAMA!J10:J5000) -> 0 | F17: =SUMIF(PROGRAMA!B10:B5000,A17,PROGRAMA!K10:K5000) -> 0 | G17: =SUMIF(PROGRAMA!B10:B5000,A17,PROGRAMA!L10:L5000) -> 0 | H17: =IFERROR(D17/C17,0) -> 1 | I17: =IFERROR((D17+E17)/(C17-F17),0) -> 1 | J17: =IF(H17>=0.9,"✅ Óptimo",IF(H17>=0.75,"⚠ Regular","❌ Crítico")) -> ✅ Óptimo | K17: =H17*0.6+I17*0.4 -> 1 | L17: =SUMIFS(MANTENIMIENTOS!L:L,MANTENIMIENTOS!N:N,B17)+SUMIFS(MANTENIMIENTOS!M:M,MANTENIMIENTOS!N:N,B17) -> 3190
A18: M-007 | B18: Grúa Puente GP-5T | C18: =COUNTIF(PROGRAMA!B10:B5000,A18) -> 4 | D18: =SUMIF(PROGRAMA!B10:B5000,A18,PROGRAMA!I10:I5000) -> 2 | E18: =SUMIF(PROGRAMA!B10:B5000,A18,PROGRAMA!J10:J5000) -> 1 | F18: =SUMIF(PROGRAMA!B10:B5000,A18,PROGRAMA!K10:K5000) -> 0 | G18: =SUMIF(PROGRAMA!B10:B5000,A18,PROGRAMA!L10:L5000) -> 1 | H18: =IFERROR(D18/C18,0) -> 0.5 | I18: =IFERROR((D18+E18)/(C18-F18),0) -> 0.75 | J18: =IF(H18>=0.9,"✅ Óptimo",IF(H18>=0.75,"⚠ Regular","❌ Crítico")) -> ❌ Crítico | K18: =H18*0.6+I18*0.4 -> 0.6 | L18: =SUMIFS(MANTENIMIENTOS!L:L,MANTENIMIENTOS!N:N,B18)+SUMIFS(MANTENIMIENTOS!M:M,MANTENIMIENTOS!N:N,B18) -> 7750
A19: M-008 | B19: Banda Transportadora BT-20 | C19: =COUNTIF(PROGRAMA!B10:B5000,A19) -> 4 | D19: =SUMIF(PROGRAMA!B10:B5000,A19,PROGRAMA!I10:I5000) -> 4 | E19: =SUMIF(PROGRAMA!B10:B5000,A19,PROGRAMA!J10:J5000) -> 0 | F19: =SUMIF(PROGRAMA!B10:B5000,A19,PROGRAMA!K10:K5000) -> 0 | G19: =SUMIF(PROGRAMA!B10:B5000,A19,PROGRAMA!L10:L5000) -> 0 | H19: =IFERROR(D19/C19,0) -> 1 | I19: =IFERROR((D19+E19)/(C19-F19),0) -> 1 | J19: =IF(H19>=0.9,"✅ Óptimo",IF(H19>=0.75,"⚠ Regular","❌ Crítico")) -> ✅ Óptimo | K19: =H19*0.6+I19*0.4 -> 1 | L19: =SUMIFS(MANTENIMIENTOS!L:L,MANTENIMIENTOS!N:N,B19)+SUMIFS(MANTENIMIENTOS!M:M,MANTENIMIENTOS!N:N,B19) -> 2830
A20: M-009 | B20: Generador Eléctrico GE-150 | C20: =COUNTIF(PROGRAMA!B10:B5000,A20) -> 4 | D20: =SUMIF(PROGRAMA!B10:B5000,A20,PROGRAMA!I10:I5000) -> 3 | E20: =SUMIF(PROGRAMA!B10:B5000,A20,PROGRAMA!J10:J5000) -> 0 | F20: =SUMIF(PROGRAMA!B10:B5000,A20,PROGRAMA!K10:K5000) -> 0 | G20: =SUMIF(PROGRAMA!B10:B5000,A20,PROGRAMA!L10:L5000) -> 1 | H20: =IFERROR(D20/C20,0) -> 0.75 | I20: =IFERROR((D20+E20)/(C20-F20),0) -> 0.75 | J20: =IF(H20>=0.9,"✅ Óptimo",IF(H20>=0.75,"⚠ Regular","❌ Crítico")) -> ⚠ Regular | K20: =H20*0.6+I20*0.4 -> 0.75 | L20: =SUMIFS(MANTENIMIENTOS!L:L,MANTENIMIENTOS!N:N,B20)+SUMIFS(MANTENIMIENTOS!M:M,MANTENIMIENTOS!N:N,B20) -> 2620
A21: M-010 | B21: Bomba Centrífuga BC-50 | C21: =COUNTIF(PROGRAMA!B10:B5000,A21) -> 4 | D21: =SUMIF(PROGRAMA!B10:B5000,A21,PROGRAMA!I10:I5000) -> 3 | E21: =SUMIF(PROGRAMA!B10:B5000,A21,PROGRAMA!J10:J5000) -> 1 | F21: =SUMIF(PROGRAMA!B10:B5000,A21,PROGRAMA!K10:K5000) -> 0 | G21: =SUMIF(PROGRAMA!B10:B5000,A21,PROGRAMA!L10:L5000) -> 0 | H21: =IFERROR(D21/C21,0) -> 0.75 | I21: =IFERROR((D21+E21)/(C21-F21),0) -> 1 | J21: =IF(H21>=0.9,"✅ Óptimo",IF(H21>=0.75,"⚠ Regular","❌ Crítico")) -> ⚠ Regular | K21: =H21*0.6+I21*0.4 -> 0.85 | L21: =SUMIFS(MANTENIMIENTOS!L:L,MANTENIMIENTOS!N:N,B21)+SUMIFS(MANTENIMIENTOS!M:M,MANTENIMIENTOS!N:N,B21) -> 2970

Sheet PROGRAMA
A1: CONTROL DE MANTENIMIENTO PREVENTIVO DE EQUIPOS — PROGRAMA ANUAL 2025
A2: Estado: E = Ejecutado | R = Reprogramado | N = No Ejecutado | P = Pendiente — Actualice la columna ESTADO
A4: Actividades | D4: Programados (PR) | G4: Ejecutados (E) | J4: Reprogramados (R) | M4: No Ejecutados (N) | P4: Pendientes (P)
A5: =COUNTA(H10:H5000) -> 40 | D5: =COUNTA(H10:H5000) -> 40 | G5: =SUM(I10:I5000) -> 32 | J5: =SUM(J10:J5000) -> 4 | M5: =SUM(K10:K5000) -> 0 | P5: =SUM(L10:L5000) -> 4
A7: % CUMPLIMIENTO | F7: % EFECTIVIDAD | K7: META CUMPLIM. ≥ 90% | O7: META EFECTIVID. ≥ 80%
A8: =IFERROR(SUM(PROGRAMA!I10:I5000)/COUNTA(PROGRAMA!H10:H5000),0) -> 0.8 | F8: =IFERROR((SUM(PROGRAMA!I10:I5000)+SUM(PROGRAMA!J10:J5000))/(COUNTA(PROGRAMA!H10:H5000)-SUM(PROGRAMA!K10:K5000)),0) -> 0.9 | K8: =CONFIG!B6 -> 0.9 | O8: =CONFIG!B7 -> 0.8
A9: N° | B9: CÓD. | C9: EQUIPO | D9: ACTIVIDAD | E9: DÍA INICIO | F9: FREC. (días) | G9: FRECUENCIA | H9: PR | I9: E | J9: R | K9: N | L9: P | M9: ESTADO | N9: CUMPLIM. | O9: EFECTIVID. | P9: PRÓX. MTTO. | Q9: FALTAN DÍAS
A10: 1 | B10: M-001 | C10: Torno CNC TL-500 | D10: Revisión y cambio de aceite del motor | E10: 01/07/2025 | F10: 30 | G10: Mensual | H10: 1 | I10: =IF(M10="E",1,0) -> 1 | J10: =IF(M10="R",1,0) -> 0 | K10: =IF(M10="N",1,0) -> 0 | L10: =IF(OR(M10="P",M10=""),1,0) -> 0 | M10: E | N10: =IF(H10>0,I10/H10,0) -> 1 | O10: =IF(H10>0,(I10+J10)/H10,0) -> 1 | P10: =IFERROR(DATE(MID(E10,7,4)*1,MID(E10,4,2)*1,LEFT(E10,2)*1)+F10,"N/A") -> 45869 | Q10: =IFERROR(P10-TODAY(),"N/A") -> -293
A11: 2 | B11: M-001 | C11: Torno CNC TL-500 | D11: Inspección eléctrica general | E11: 16/07/2025 | F11: 15 | G11: Quincenal | H11: 1 | I11: =IF(M11="E",1,0) -> 1 | J11: =IF(M11="R",1,0) -> 0 | K11: =IF(M11="N",1,0) -> 0 | L11: =IF(OR(M11="P",M11=""),1,0) -> 0 | M11: E | N11: =IF(H11>0,I11/H11,0) -> 1 | O11: =IF(H11>0,(I11+J11)/H11,0) -> 1 | P11: =IFERROR(DATE(MID(E11,7,4)*1,MID(E11,4,2)*1,LEFT(E11,2)*1)+F11,"N/A") -> 45869 | Q11: =IFERROR(P11-TODAY(),"N/A") -> -293
A12: 3 | B12: M-002 | C12: Fresadora Vertical FV-300 | D12: Inspección del sistema hidráulico | E12: 03/07/2025 | F12: 7 | G12: Semanal | H12: 1 | I12: =IF(M12="E",1,0) -> 1 | J12: =IF(M12="R",1,0) -> 0 | K12: =IF(M12="N",1,0) -> 0 | L12: =IF(OR(M12="P",M12=""),1,0) -> 0 | M12: E | N12: =IF(H12>0,I12/H12,0) -> 1 | O12: =IF(H12>0,(I12+J12)/H12,0) -> 1 | P12: =IFERROR(DATE(MID(E12,7,4)*1,MID(E12,4,2)*1,LEFT(E12,2)*1)+F12,"N/A") -> 45848 | Q12: =IFERROR(P12-TODAY(),"N/A") -> -314
A13: 4 | B13: M-002 | C13: Fresadora Vertical FV-300 | D13: Lubricación de partes móviles | E13: 03/07/2025 | F13: 7 | G13: Semanal | H13: 1 | I13: =IF(M13="E",1,0) -> 0 | J13: =IF(M13="R",1,0) -> 1 | K13: =IF(M13="N",1,0) -> 0 | L13: =IF(OR(M13="P",M13=""),1,0) -> 0 | M13: R | N13: =IF(H13>0,I13/H13,0) -> 0 | O13: =IF(H13>0,(I13+J13)/H13,0) -> 1 | P13: =IFERROR(DATE(MID(E13,7,4)*1,MID(E13,4,2)*1,LEFT(E13,2)*1)+F13,"N/A") -> 45848 | Q13: =IFERROR(P13-TODAY(),"N/A") -> -314
A14: 5 | B14: M-003 | C14: Taladro Radial TR-200 | D14: Limpieza de filtros y sistema de enfriamiento | E14: 05/07/2025 | F14: 30 | G14: Mensual | H14: 1 | I14: =IF(M14="E",1,0) -> 1 | J14: =IF(M14="R",1,0) -> 0 | K14: =IF(M14="N",1,0) -> 0 | L14: =IF(OR(M14="P",M14=""),1,0) -> 0 | M14: E | N14: =IF(H14>0,I14/H14,0) -> 1 | O14: =IF(H14>0,(I14+J14)/H14,0) -> 1 | P14: =IFERROR(DATE(MID(E14,7,4)*1,MID(E14,4,2)*1,LEFT(E14,2)*1)+F14,"N/A") -> 45873 | Q14: =IFERROR(P14-TODAY(),"N/A") -> -289
A15: 6 | B15: M-003 | C15: Taladro Radial TR-200 | D15: Revisión de frenos y sistema de parada | E15: 20/07/2025 | F15: 15 | G15: Quincenal | H15: 1 | I15: =IF(M15="E",1,0) -> 0 | J15: =IF(M15="R",1,0) -> 0 | K15: =IF(M15="N",1,0) -> 0 | L15: =IF(OR(M15="P",M15=""),1,0) -> 1 | M15: P | N15: =IF(H15>0,I15/H15,0) -> 0 | O15: =IF(H15>0,(I15+J15)/H15,0) -> 0 | P15: =IFERROR(DATE(MID(E15,7,4)*1,MID(E15,4,2)*1,LEFT(E15,2)*1)+F15,"N/A") -> 45873 | Q15: =IFERROR(P15-TODAY(),"N/A") -> -289
A16: 7 | B16: M-004 | C16: Soldadora MIG SW-450 | D16: Inspección de soldaduras y estructuras | E16: 07/07/2025 | F16: 30 | G16: Mensual | H16: 1 | I16: =IF(M16="E",1,0) -> 0 | J16: =IF(M16="R",1,0) -> 1 | K16: =IF(M16="N",1,0) -> 0 | L16: =IF(OR(M16="P",M16=""),1,0) -> 0 | M16: R | N16: =IF(H16>0,I16/H16,0) -> 0 | O16: =IF(H16>0,(I16+J16)/H16,0) -> 1 | P16: =IFERROR(DATE(MID(E16,7,4)*1,MID(E16,4,2)*1,LEFT(E16,2)*1)+F16,"N/A") -> 45875 | Q16: =IFERROR(P16-TODAY(),"N/A") -> -287
A17: 8 | B17: M-004 | C17: Soldadora MIG SW-450 | D17: Calibración de parámetros y sensores | E17: 07/07/2025 | F17: 60 | G17: Bimestral | H17: 1 | I17: =IF(M17="E",1,0) -> 0 | J17: =IF(M17="R",1,0) -> 0 | K17: =IF(M17="N",1,0) -> 0 | L17: =IF(OR(M17="P",M17=""),1,0) -> 1 | M17: P | N17: =IF(H17>0,I17/H17,0) -> 0 | O17: =IF(H17>0,(I17+J17)/H17,0) -> 0 | P17: =IFERROR(DATE(MID(E17,7,4)*1,MID(E17,4,2)*1,LEFT(E17,2)*1)+F17,"N/A") -> 45905 | Q17: =IFERROR(P17-TODAY(),"N/A") -> -257
A18: 9 | B18: M-005 | C18: Compresor Industrial CI-75 | D18: Limpieza de filtros y sistema de enfriamiento | E18: 08/07/2025 | F18: 15 | G18: Quincenal | H18: 1 | I18: =IF(M18="E",1,0) -> 1 | J18: =IF(M18="R",1,0) -> 0 | K18: =IF(M18="N",1,0) -> 0 | L18: =IF(OR(M18="P",M18=""),1,0) -> 0 | M18: E | N18: =IF(H18>0,I18/H18,0) -> 1 | O18: =IF(H18>0,(I18+J18)/H18,0) -> 1 | P18: =IFERROR(DATE(MID(E18,7,4)*1,MID(E18,4,2)*1,LEFT(E18,2)*1)+F18,"N/A") -> 45861 | Q18: =IFERROR(P18-TODAY(),"N/A") -> -301
A19: 10 | B19: M-005 | C19: Compresor Industrial CI-75 | D19: Revisión y cambio de aceite del motor | E19: 23/07/2025 | F19: 30 | G19: Mensual | H19: 1 | I19: =IF(M19="E",1,0) -> 1 | J19: =IF(M19="R",1,0) -> 0 | K19: =IF(M19="N",1,0) -> 0 | L19: =IF(OR(M19="P",M19=""),1,0) -> 0 | M19: E | N19: =IF(H19>0,I19/H19,0) -> 1 | O19: =IF(H19>0,(I19+J19)/H19,0) -> 1 | P19: =IFERROR(DATE(MID(E19,7,4)*1,MID(E19,4,2)*1,LEFT(E19,2)*1)+F19,"N/A") -> 45891 | Q19: =IFERROR(P19-TODAY(),"N/A") -> -271
A20: 11 | B20: M-006 | C20: Prensa Hidráulica PH-100 | D20: Inspección del sistema hidráulico | E20: 10/07/2025 | F20: 7 | G20: Semanal | H20: 1 | I20: =IF(M20="E",1,0) -> 1 | J20: =IF(M20="R",1,0) -> 0 | K20: =IF(M20="N",1,0) -> 0 | L20: =IF(OR(M20="P",M20=""),1,0) -> 0 | M20: E | N20: =IF(H20>0,I20/H20,0) -> 1 | O20: =IF(H20>0,(I20+J20)/H20,0) -> 1 | P20: =IFERROR(DATE(MID(E20,7,4)*1,MID(E20,4,2)*1,LEFT(E20,2)*1)+F20,"N/A") -> 45855 | Q20: =IFERROR(P20-TODAY(),"N/A") -> -307
A21: 12 | B21: M-006 | C21: Prensa Hidráulica PH-100 | D21: Revisión de correas y poleas | E21: 10/07/2025 | F21: 60 | G21: Bimestral | H21: 1 | I21: =IF(M21="E",1,0) -> 1 | J21: =IF(M21="R",1,0) -> 0 | K21: =IF(M21="N",1,0) -> 0 | L21: =IF(OR(M21="P",M21=""),1,0) -> 0 | M21: E | N21: =IF(H21>0,I21/H21,0) -> 1 | O21: =IF(H21>0,(I21+J21)/H21,0) -> 1 | P21: =IFERROR(DATE(MID(E21,7,4)*1,MID(E21,4,2)*1,LEFT(E21,2)*1)+F21,"N/A") -> 45908 | Q21: =IFERROR(P21-TODAY(),"N/A") -> -254
... A49: 40 | B49: M-010 | C49: Bomba Centrífuga BC-50 | D49: Calibración de presostatos y válvulas de regulación | E49: 17/04/2025 | F49: 60 | G49: Bimestral | H49: 1 | I49: =IF(M49="E",1,0) -> 0 | J49: =IF(M49="R",1,0) -> 1 | K49: =IF(M49="N",1,0) -> 0 | L49: =IF(OR(M49="P",M49=""),1,0) -> 0 | M49: R | N49: =IF(H49>0,I49/H49,0) -> 0 | O49: =IF(H49>0,(I49+J49)/H49,0) -> 1 | P49: =IFERROR(DATE(MID(E49,7,4)*1,MID(E49,4,2)*1,LEFT(E49,2)*1)+F49,"N/A") -> 45824 | Q49: =IFERROR(P49-TODAY(),"N/A") -> -338

Sheet PROG_CM
A1: PROGRAMA DE MANTENIMIENTO CORRECTIVO — 2025
A2: Registre fallas detectadas y programe su intervención. Actualice ESTADO al ejecutar. | PRIORIDAD: Alta / Media / Baja
A3: TOTAL REGISTROS | C3: PENDIENTES | E3: EN PROCESO | G3: COMPLETADOS | I3: COSTO M.O. TOTAL | K3: COSTO INSUMOS TOTAL | M3: COSTO TOTAL CM | O3: % DEL PRESUPUESTO
A4: =COUNTA(A7:A500) -> 12 | C4: =COUNTIF(N7:N500,"Pendiente") -> 4 | E4: =COUNTIF(N7:N500,"En Proceso") -> 0 | G4: =COUNTIF(N7:N500,"Completado") -> 6 | I4: =IFERROR(SUM(K7:K500),0) -> 15000 | K4: =IFERROR(SUM(L7:L500),0) -> 25700 | M4: =IFERROR(SUM(K7:K500)+SUM(L7:L500),0) -> 40700 | O4: =IFERROR((SUM(K7:K500)+SUM(L7:L500))/42550,0) -> 0.95652174
A5: IDENTIFICACIÓN DEL EQUIPO Y FALLA | E5: FECHAS DE INTERVENCIÓN | H5: RECURSOS | K5: COSTOS (MXN) | N5: ESTADO | O5: OBSERVACIONES
A6: N° | B6: CÓD. EQUIPO | C6: NOMBRE DEL EQUIPO | D6: FALLA DETECTADA / DESCRIPCIÓN | E6: FECHA DETECCIÓN | F6: FECHA PROGRAMADA | G6: FECHA EJECUCIÓN | H6: RESPONSABLE | I6: PRIORIDAD | J6: TIEMPO REP. (min) | K6: COSTO M.O. ($) | L6: COSTO INSUMOS ($) | M6: COSTO TOTAL ($) | N6: ESTADO | O6: OBSERVACIONES
A7: 1 | B7: M-003 | C7: Taladro Radial TR-200 | D7: Rodamiento principal con desgaste severo — sustitución completa | E7: 20/01/2025 | F7: 20/01/2025 | G7: 20/01/2025 | H7: RESPONSABLE B | I7: Alta | J7: 240 | K7: 1200 | L7: 2100 | M7: =K7+L7 -> 3300 | N7: Completado | O7: Rodamiento SKF 6205 x4. Equipo regresó a operación el mismo día.
A8: 2 | B8: M-002 | C8: Fresadora Vertical FV-300 | D8: Fuga hidráulica en cilindro principal — sellos y manguera | E8: 20/02/2025 | F8: 20/02/2025 | G8: 20/02/2025 | H8: RESPONSABLE C | I8: Alta | J8: 300 | K8: 1500 | L8: 3200 | M8: =K8+L8 -> 4700 | N8: Completado | O8: Manguera 1/2" x4m + sellos mecánicos x2. Mayor correctivo del año en costo.
A9: 3 | B9: M-007 | C9: Grúa Puente GP-5T | D9: Desgaste en polipasto — cable de acero y rodamientos de gancho | E9: 18/03/2025 | F9: 18/03/2025 | G9: 19/03/2025 | H9: RESPONSABLE A | I9: Alta | J9: 360 | K9: 1800 | L9: 3800 | M9: =K9+L9 -> 5600 | N9: Completado | O9: Cable nuevo + rodamientos de gancho. Entrega al día siguiente por tiempo de reparación.
A10: 4 | B10: M-004 | C10: Soldadora MIG SW-450 | D10: Falla eléctrica en fuente de poder — diagnóstico y reparación | E10: 02/04/2025 | F10: 02/04/2025 | G10: 02/04/2025 | H10: RESPONSABLE B | I10: Alta | J10: 240 | K10: 1200 | L10: 1800 | M10: =K10+L10 -> 3000 | N10: Completado | O10: Fusibles + cable THW. Falla relacionada con PM pendiente de calibración.
A11: 5 | B11: M-010 | C11: Bomba Centrífuga BC-50 | D11: Reemplazo de sello mecánico — fuga en caudal de salida | E11: 18/04/2025 | F11: 18/04/2025 | G11: 18/04/2025 | H11: RESPONSABLE E | I11: Media | J11: 180 | K11: 900 | L11: 1300 | M11: =K11+L11 -> 2200 | N11: Completado | O11: Sello mecánico sustituido. Caudal dentro de parámetros post-reparación.
A12: 6 | B12: M-008 | C12: Banda Transportadora BT-20 | D12: Desalineación severa de banda — corrección de rodillos y guía lateral | E12: 25/05/2025 | F12: 25/05/2025 | G12: 25/05/2025 | H12: RESPONSABLE A | I12: Media | J12: 180 | K12: 900 | L12: 650 | M12: =K12+L12 -> 1550 | N12: Completado | O12: Tensado y alineación. Monitoreo mensual preventivo activado.
A13: 7 | B13: M-007 | C13: Grúa Puente GP-5T | D13: Cable de acero nuevo — desgaste progresivo detectado en inspección | E13: 18/05/2025 | F13: ⚠ POR DEFINIR | G13: — | H13: RESPONSABLE A | I13: Alta | J13: — | K13: — | L13: — | M13: — | N13: Pendiente | O13: Pendiente de cotización y presupuesto Q4 2025. Ver MAQUINAS obs. M-007.
A14: 8 | B14: M-004 | C14: Soldadora MIG SW-450 | D14: Revisión mayor Q4 2025 — acumulación de fallas eléctricas en el año | E14: 18/05/2025 | F14: ⚠ POR DEFINIR | G14: — | H14: RESPONSABLE B | I14: Alta | J14: — | K14: — | L14: — | M14: — | N14: Pendiente | O14: Coordinar con proveedor LINCOLN para revisión mayor Q4.
A15: 9 | B15: M-009 | C15: Generador Eléctrico GE-150 | D15: Cambio de inyectores Q4 2025 — operación continua 24/7 | E15: 18/05/2025 | F15: ⚠ POR DEFINIR | G15: — | H15: RESPONSABLE D | I15: Media | J15: — | K15: — | L15: — | M15: — | N15: Pendiente | O15: Cambio preventivo-correctivo de inyectores CUMMINS programado Q4.
A16: 10 | B16: M-005 | C16: Compresor Industrial CI-75 | D16: Revisión anual de válvulas Nov 2025 — equipo con 9 años de antigüedad | E16: 18/05/2025 | F16: ⚠ POR DEFINIR | G16: — | H16: RESPONSABLE C | I16: Media | J16: — | K16: — | L16: — | M16: — | N16: Pendiente | O16: Mayor frecuencia de PM recomendada. Rev. válvulas admisión/descarga Nov 2025.
A17: TOTALES EJECUTADOS | K17: =IFERROR(SUMIF(N7:N16,"Completado",K7:K16),0) -> 7500 | L17: =IFERROR(SUMIF(N7:N16,"Completado",L7:L16),0) -> 12850 | M17: =IFERROR(K17+L17,0) -> 20350
A19: LEYENDA: | B19: ✅ Completado | C19: ⏳ En Proceso | D19: ⚠ Pendiente | E19: ⚠ POR DEFINIR = Fecha programada pendiente de asignar

Sheet MAQUINAS
A1: REGISTRO DE MÁQUINAS Y EQUIPOS
A2: Complete todos los campos. CÓDIGO debe ser único. Estado: Operativo / En Mantenimiento / Fuera de Servicio
A3: DATOS GENERALES | H3: OPERACIÓN | K3: ESTADO | L3: INDICADOR | M3: NOTAS
A4: N° | B4: CÓDIGO | C4: NOMBRE DEL EQUIPO | D4: TIPO | E4: MARCA | F4: UBICACIÓN | G4: FECHA ADQUIS. | H4: ANTIGÜEDAD (años) | I4: HRS/DÍA | J4: CRITICIDAD | K4: ESTADO | L4: MTTR (promedio) | M4: OBSERVACIONES
A5: 1 | B5: M-001 | C5: Torno CNC TL-500 | D5: Mecanizado | E5: HAAS | F5: Taller A | G5: 15/03/2019 | H5: =IFERROR(DATEDIF(DATE(MID(G5,7,4),MID(G5,4,2),LEFT(G5,2)),TODAY(),"Y"),"") -> 7 | I5: 8 | J5: Alta | K5: Operativo | L5: =IFERROR(AVERAGEIF(MANTENIMIENTOS!B:B,B5,MANTENIMIENTOS!I:I),"-") -> - | M5: 6 años en servicio. CM correctivo Ene 2025 (rodamiento). Sin paros no programados Q2.
A6: 2 | B6: M-002 | C6: Fresadora Vertical FV-300 | D6: Mecanizado | E6: FANUC | F6: Taller A | G6: 20/07/2018 | H6: =IFERROR(DATEDIF(DATE(MID(G6,7,4),MID(G6,4,2),LEFT(G6,2)),TODAY(),"Y"),"") -> 7 | I6: 8 | J6: Alta | K6: Operativo | L6: =IFERROR(AVERAGEIF(MANTENIMIENTOS!B:B,B6,MANTENIMIENTOS!I:I),"-") -> - | M6: 7 años. Fuga hidráulica corregida Feb 2025. Desempeño óptimo post-reparación.
A7: 3 | B7: M-003 | C7: Taladro Radial TR-200 | D7: Perforación | E7: KNUTH | F7: Taller B | G7: 10/01/2020 | H7: =IFERROR(DATEDIF(DATE(MID(G7,7,4),MID(G7,4,2),LEFT(G7,2)),TODAY(),"Y"),"") -> 6 | I7: 6 | J7: Media | K7: Operativo | L7: =IFERROR(AVERAGEIF(MANTENIMIENTOS!B:B,B7,MANTENIMIENTOS!I:I),"-") -> - | M7: 5 años. Rodamiento reemplazado Ene 2025. Monitoreo de vibración cada 15 días.
A8: 4 | B8: M-004 | C8: Soldadora MIG SW-450 | D8: Soldadura | E8: LINCOLN | F8: Taller B | G8: 05/06/2017 | H8: =IFERROR(DATEDIF(DATE(MID(G8,7,4),MID(G8,4,2),LEFT(G8,2)),TODAY(),"Y"),"") -> 8 | I8: 8 | J8: Alta | K8: Operativo | L8: =IFERROR(AVERAGEIF(MANTENIMIENTOS!B:B,B8,MANTENIMIENTOS!I:I),"-") -> - | M8: 8 años. Falla fuente de poder corregida Abr 2025. Próxima rev. mayor Q4 2025.
A9: 5 | B9: M-005 | C9: Compresor Industrial CI-75 | D9: Neumática | E9: ATLAS | F9: Sala Comp. | G9: 12/11/2016 | H9: =IFERROR(DATEDIF(DATE(MID(G9,7,4),MID(G9,4,2),LEFT(G9,2)),TODAY(),"Y"),"") -> 9 | I9: 8 | J9: Alta | K9: Operativo | L9: =IFERROR(AVERAGEIF(MANTENIMIENTOS!B:B,B9,MANTENIMIENTOS!I:I),"-") -> - | M9: 9 años. Mayor frecuencia de PM. Rev. anual de válvulas programada Nov 2025.
A10: 6 | B10: M-006 | C10: Prensa Hidráulica PH-100 | D10: Prensado | E10: ENERPAC | F10: Taller C | G10: 08/04/2021 | H10: =IFERROR(DATEDIF(DATE(MID(G10,7,4),MID(G10,4,2),LEFT(G10,2)),TODAY(),"Y"),"") -> 5 | I10: 6 | J10: Alta | K10: Operativo | L10: =IFERROR(AVERAGEIF(MANTENIMIENTOS!B:B,B10,MANTENIMIENTOS!I:I),"-") -> - | M10: 4 años. Hidráulico en óptimas condiciones. Certificación NOM programada Sep 2025.
A11: 7 | B11: M-007 | C11: Grúa Puente GP-5T | D11: Izaje | E11: DEMAG | F11: Nave Ppal | G11: 30/09/2015 | H11: =IFERROR(DATEDIF(DATE(MID(G11,7,4),MID(G11,4,2),LEFT(G11,2)),TODAY(),"Y"),"") -> 10 | I11: 8 | J11: Alta | K11: Operativo | L11: =IFERROR(AVERAGEIF(MANTENIMIENTOS!B:B,B11,MANTENIMIENTOS!I:I),"-") -> - | M11: 10 años. CM polipasto Mar 2025. Cotizar cable nuevo para plan capital 2026.
A12: 8 | B12: M-008 | C12: Banda Transportadora BT-20 | D12: Transporte | E12: REXNORD | F12: Línea 1 | G12: 22/02/2022 | H12: =IFERROR(DATEDIF(DATE(MID(G12,7,4),MID(G12,4,2),LEFT(G12,2)),TODAY(),"Y"),"") -> 4 | I12: 8 | J12: Media | K12: Operativo | L12: =IFERROR(AVERAGEIF(MANTENIMIENTOS!B:B,B12,MANTENIMIENTOS!I:I),"-") -> - | M12: 3 años. CM desalineación May 2025. Tensado y alineación mensual preventivo.
A13: 9 | B13: M-009 | C13: Generador Eléctrico GE-150 | D13: Eléctrico | E13: CUMMINS | F13: Sala Gen. | G13: 14/08/2019 | H13: =IFERROR(DATEDIF(DATE(MID(G13,7,4),MID(G13,4,2),LEFT(G13,2)),TODAY(),"Y"),"") -> 6 | I13: 24 | J13: Alta | K13: Operativo | L13: =IFERROR(AVERAGEIF(MANTENIMIENTOS!B:B,B13,MANTENIMIENTOS!I:I),"-") -> - | M13: 6 años. Operación 24/7. Cambio de inyectores programado Q4 2025.
A14: 10 | B14: M-010 | C14: Bomba Centrífuga BC-50 | D14: Hidráulica | E14: GRUNDFOS | F14: Sala Bom. | G14: 03/12/2020 | H14: =IFERROR(DATEDIF(DATE(MID(G14,7,4),MID(G14,4,2),LEFT(G14,2)),TODAY(),"Y"),"") -> 5 | I14: 16 | J14: Media | K14: Operativo | L14: =IFERROR(AVERAGEIF(MANTENIMIENTOS!B:B,B14,MANTENIMIENTOS!I:I),"-") -> - | M14: 5 años. Sello mecánico sustituido Abr 2025. Caudal dentro de parámetros.

Sheet MANTENIMIENTOS
A1: HISTORIAL DE MANTENIMIENTOS — PREVENTIVO Y CORRECTIVO
A2: Registre cada intervención. Tipo: TRUE = Preventivo | FALSE = Correctivo. Estado actualiza KPIs automáticamente.
A4: TOTAL REGISTROS | D4: PREVENTIVOS | G4: CORRECTIVOS | J4: COSTO MO TOTAL | M4: COSTO INSUMOS TOTAL
A5: =COUNTA(A11:A5000) -> 30 | D5: =COUNTIF(E11:E5000,TRUE()) -> 24 | G5: =COUNTIF(E11:E5000,FALSE()) -> 6 | J5: =SUM(L11:L5000) -> 19950 | M5: =SUM(M11:M5000) -> 22600
A8: IDENTIFICACIÓN | E8: TIPO Y RESPONSABLE | I8: TIEMPOS Y COSTOS | M8: NOMBRE | O8: AUTORIZACIÓN
A9: ID | B9: MÁQUINA (ID) | C9: FECHA | D9: HORA | E9: TIPO PM=✓ CM=✗ | F9: RESPONSABLE | G9: OBSERVACIONES | H9: REALIZADO ✓/✗ | I9: TIEMPO REP.(min) | J9: FECHA ENTREGA | K9: DÍAS PREV. | L9: COSTO M.O. | M9: COSTO INSUMOS | N9: EQUIPO (nombre) | O9: HECHO POR | P9: AUTORIZADO
A10: ▶ Ingrese datos desde el formulario (Menú principal) o directamente en esta tabla. Las columnas N a P se calculan automáticamente.
A11: 1 | B11: 1 | C11: 08/01/2025 | D11: 08:00 | E11: =TRUE() -> TRUE | F11: RESPONSABLE A | G11: Cambio de aceite SAE 40, filtro de motor y puntos de lubricación | H11: =TRUE() -> TRUE | I11: 120 | J11: 08/01/2025 | K11: 30 | L11: 550 | M11: 780 | N11: Torno CNC TL-500 | O11: RESPONSABLE A | P11: Ing. Carlos Martínez López
A12: 2 | B12: 2 | C12: 10/01/2025 | D12: 09:00 | E12: =TRUE() -> TRUE | F12: RESPONSABLE B | G12: Inspección del sistema hidráulico y verificación de nivel de aceite | H12: =TRUE() -> TRUE | I12: 90 | J12: 10/01/2025 | K12: 30 | L12: 450 | M12: 320 | N12: Fresadora Vertical FV-300 | O12: RESPONSABLE B | P12: Ing. Carlos Martínez López
A13: 3 | B13: 5 | C13: 12/01/2025 | D13: 10:00 | E13: =TRUE() -> TRUE | F13: RESPONSABLE C | G13: Limpieza de filtros separadores y revisión del sistema de ventilación | H13: =TRUE() -> TRUE | I13: 60 | J13: 12/01/2025 | K13: 15 | L13: 350 | M13: 180 | N13: Compresor Industrial CI-75 | O13: RESPONSABLE C | P13: Ing. Carlos Martínez López
A14: 4 | B14: 7 | C14: 15/01/2025 | D14: 08:30 | E14: =TRUE() -> TRUE | F14: RESPONSABLE A | G14: Inspección estructural completa, soldaduras y cables de acero del polipasto | H14: =TRUE() -> TRUE | I14: 150 | J14: 15/01/2025 | K14: 30 | L14: 750 | M14: 450 | N14: Grúa Puente GP-5T | O14: RESPONSABLE A | P14: Ing. Carlos Martínez López
A15: 5 | B15: 3 | C15: 20/01/2025 | D15: 07:00 | E15: =FALSE() -> FALSE | F15: RESPONSABLE B | G15: CORRECTIVO: Rodamiento principal con desgaste severo — sustitución completa | H15: =TRUE() -> TRUE | I15: 240 | J15: 20/01/2025 | K15: 0 | L15: 1200 | M15: 2100 | N15: Taladro Radial TR-200 | O15: RESPONSABLE B | P15: Ing. Carlos Martínez López
A16: 6 | B16: 1 | C16: 05/02/2025 | D16: 09:00 | E16: =TRUE() -> TRUE | F16: RESPONSABLE A | G16: Inspección eléctrica general y ajuste fino de parámetros CNC | H16: =TRUE() -> TRUE | I16: 90 | J16: 05/02/2025 | K16: 30 | L16: 450 | M16: 280 | N16: Torno CNC TL-500 | O16: RESPONSABLE A | P16: Ing. Carlos Martínez López
A17: 7 | B17: 6 | C17: 07/02/2025 | D17: 08:00 | E17: =TRUE() -> TRUE | F17: RESPONSABLE E | G17: Inspección sistema hidráulico — sellos, válvulas y presión del circuito | H17: =TRUE() -> TRUE | I17: 120 | J17: 07/02/2025 | K17: 7 | L17: 600 | M17: 580 | N17: Prensa Hidráulica PH-100 | O17: RESPONSABLE E | P17: Ing. Carlos Martínez López
A18: 8 | B18: 9 | C18: 10/02/2025 | D18: 08:00 | E18: =TRUE() -> TRUE | F18: RESPONSABLE D | G18: Inspección eléctrica del tablero, cableado y terminales del generador | H18: =TRUE() -> TRUE | I18: 120 | J18: 10/02/2025 | K18: 15 | L18: 600 | M18: 420 | N18: Generador Eléctrico GE-150 | O18: RESPONSABLE D | P18: Ing. Carlos Martínez López
A19: 9 | B19: 4 | C19: 14/02/2025 | D19: 09:30 | E19: =TRUE() -> TRUE | F19: RESPONSABLE B | G19: Inspección de mordazas, soldaduras y calibración de parámetros MIG | H19: =TRUE() -> TRUE | I19: 90 | J19: 14/02/2025 | K19: 30 | L19: 450 | M19: 250 | N19: Soldadora MIG SW-450 | O19: RESPONSABLE B | P19: Ing. Carlos Martínez López
A20: 10 | B20: 2 | C20: 20/02/2025 | D20: 07:00 | E20: =FALSE() -> FALSE | F20: RESPONSABLE C | G20: CORRECTIVO: Fuga hidráulica en cilindro principal — sellos y manguera | H20: =TRUE() -> TRUE | I20: 300 | J20: 20/02/2025 | K20: 0 | L20: 1500 | M20: 3200 | N20: Fresadora Vertical FV-300 | O20: RESPONSABLE C | P20: Ing. Carlos Martínez López
A21: 11 | B21: 8 | C21: 25/02/2025 | D21: 10:00 | E21: =TRUE() -> TRUE | F21: RESPONSABLE A | G21: Lubricación general de rodillos, tambor motriz y estructura de banda | H21: =TRUE() -> TRUE | I21: 60 | J21: 25/02/2025 | K21: 7 | L21: 300 | M21: 150 | N21: Banda Transportadora BT-20 | O21: RESPONSABLE A | P21: Ing. Carlos Martínez López
A22: 12 | B22: 10 | C22: 28/02/2025 | D22: 09:00 | E22: =TRUE() -> TRUE | F22: RESPONSABLE E | G22: Inspección de sellos mecánicos, impulsores y verificación de caudal | H22: =TRUE() -> TRUE | I22: 90 | J22: 28/02/2025 | K22: 7 | L22: 450 | M22: 320 | N22: Bomba Centrífuga BC-50 | O22: RESPONSABLE E | P22: Ing. Carlos Martínez López
A23: 13 | B23: 1 | C23: 10/03/2025 | D23: 08:00 | E23: =TRUE() -> TRUE | F23: RESPONSABLE A | G23: Cambio de aceite de motor SAE 40 — ciclo mensual y engrase de puntos | H23: =TRUE() -> TRUE | I23: 120 | J23: 10/03/2025 | K23: 30 | L23: 550 | M23: 780 | N23: Torno CNC TL-500 | O23: RESPONSABLE A | P23: Ing. Carlos Martínez López
A24: 14 | B24: 5 | C24: 15/03/2025 | D24: 09:00 | E24: =TRUE() -> TRUE | F24: RESPONSABLE C | G24: Revisión y cambio de aceite del compresor, filtro de línea y trampa | H24: =TRUE() -> TRUE | I24: 150 | J24: 15/03/2025 | K24: 30 | L24: 750 | M24: 650 | N24: Compresor Industrial CI-75 | O24: RESPONSABLE C | P24: Ing. Carlos Martínez López
A25: 15 | B25: 7 | C25: 18/03/2025 | D25: 07:00 | E25: =FALSE() -> FALSE | F25: RESPONSABLE A | G25: CORRECTIVO: Desgaste en polipasto — cable de acero y rodamientos de gancho | H25: =TRUE() -> TRUE | I25: 360 | J25: 19/03/2025 | K25: 0 | L25: 1800 | M25: 3800 | N25: Grúa Puente GP-5T | O25: RESPONSABLE A | P25: Ing. Carlos Martínez López
A26: 16 | B26: 3 | C26: 22/03/2025 | D26: 10:00 | E26: =TRUE() -> TRUE | F26: RESPONSABLE B | G26: Limpieza de filtros de refrigerante y revisión de bomba de enfriamiento | H26: =TRUE() -> TRUE | I26: 60 | J26: 22/03/2025 | K26: 30 | L26: 300 | M26: 180 | N26: Taladro Radial TR-200 | O26: RESPONSABLE B | P26: Ing. Carlos Martínez López
A27: 17 | B27: 6 | C27: 25/03/2025 | D27: 08:00 | E27: =TRUE() -> TRUE | F27: RESPONSABLE E | G27: Revisión de correas trapezoidales, poleas y tensión de aprietes | H27: =TRUE() -> TRUE | I27: 90 | J27: 25/03/2025 | K27: 60 | L27: 450 | M27: 380 | N27: Prensa Hidráulica PH-100 | O27: RESPONSABLE E | P27: Ing. Carlos Martínez López
A28: 18 | B28: 4 | C28: 02/04/2025 | D28: 07:00 | E28: =FALSE() -> FALSE | F28: RESPONSABLE B | G28: CORRECTIVO: Diagnóstico y reparación de falla eléctrica en fuente de poder | H28: =TRUE() -> TRUE | I28: 240 | J28: 02/04/2025 | K28: 0 | L28: 1200 | M28: 1800 | N28: Soldadora MIG SW-450 | O28: RESPONSABLE B | P28: Ing. Carlos Martínez López
A29: 19 | B29: 2 | C29: 05/04/2025 | D29: 09:00 | E29: =TRUE() -> TRUE | F29: RESPONSABLE B | G29: Lubricación de guías lineales, husillos esféricos y mesa de trabajo | H29: =TRUE() -> TRUE | I29: 60 | J29: 05/04/2025 | K29: 7 | L29: 300 | M29: 150 | N29: Fresadora Vertical FV-300 | O29: RESPONSABLE B | P29: Ing. Carlos Martínez López
A30: 20 | B30: 8 | C30: 10/04/2025 | D30: 10:00 | E30: =TRUE() -> TRUE | F30: RESPONSABLE A | G30: Revisión y tensado de correa transportadora y alineación de rodillos | H30: =TRUE() -> TRUE | I30: 90 | J30: 10/04/2025 | K30: 30 | L30: 450 | M30: 380 | N30: Banda Transportadora BT-20 | O30: RESPONSABLE A | P30: Ing. Carlos Martínez López
A31: 21 | B31: 9 | C31: 15/04/2025 | D31: 08:00 | E31: =TRUE() -> TRUE | F31: RESPONSABLE D | G31: Cambio de aceite de motor, filtro de combustible y revisión de alternador | H31: =TRUE() -> TRUE | I31: 150 | J31: 15/04/2025 | K31: 60 | L31: 750 | M31: 850 | N31: Generador Eléctrico GE-150 | O31: RESPONSABLE D | P31: Ing. Carlos Martínez López
A32: 22 | B32: 10 | C32: 18/04/2025 | D32: 07:00 | E32: =FALSE() -> FALSE | F32: RESPONSABLE E | G32: CORRECTIVO: Reemplazo de sello mecánico — fuga en caudal de salida | H32: =TRUE() -> TRUE | I32: 180 | J32: 18/04/2025 | K32: 0 | L32: 900 | M32: 1300 | N32: Bomba Centrífuga BC-50 | O32: RESPONSABLE E | P32: Ing. Carlos Martínez López
A33: 23 | B33: 1 | C33: 25/04/2025 | D33: 09:00 | E33: =TRUE() -> TRUE | F33: RESPONSABLE A | G33: Calibración de parámetros CNC, compensaciones de herramienta y ciclo de prueba | H33: =TRUE() -> TRUE | I33: 180 | J33: 25/04/2025 | K33: 90 | L33: 900 | M33: 520 | N33: Torno CNC TL-500 | O33: RESPONSABLE A | P33: Ing. Carlos Martínez López
A34: 24 | B34: 5 | C34: 03/05/2025 | D34: 10:00 | E34: =TRUE() -> TRUE | F34: RESPONSABLE C | G34: Limpieza de filtros separadores de agua-aceite y revisión de válvulas de alivio | H34: =TRUE() -> TRUE | I34: 60 | J34: 03/05/2025 | K34: 15 | L34: 350 | M34: 180 | N34: Compresor Industrial CI-75 | O34: RESPONSABLE C | P34: Ing. Carlos Martínez López
A35: 25 | B35: 6 | C35: 06/05/2025 | D35: 08:00 | E35: =TRUE() -> TRUE | F35: RESPONSABLE E | G35: Inspección de cilindro hidráulico, válvulas de control y presión del sistema | H35: =TRUE() -> TRUE | I35: 120 | J35: 06/05/2025 | K35: 7 | L35: 600 | M35: 580 | N35: Prensa Hidráulica PH-100 | O35: RESPONSABLE E | P35: Ing. Carlos Martínez López
A36: 26 | B36: 7 | C36: 10/05/2025 | D36: 09:00 | E36: =TRUE() -> TRUE | F36: RESPONSABLE A | G36: Revisión de tablero de control, finales de carrera y limitadores de sobrecarga | H36: =TRUE() -> TRUE | I36: 120 | J36: 10/05/2025 | K36: 15 | L36: 600 | M36: 350 | N36: Grúa Puente GP-5T | O36: RESPONSABLE A | P36: Ing. Carlos Martínez López
A37: 27 | B37: 3 | C37: 12/05/2025 | D37: 10:00 | E37: =TRUE() -> TRUE | F37: RESPONSABLE B | G37: Revisión del sistema de frenos neumático y mecanismo de parada de emergencia | H37: =TRUE() -> TRUE | I37: 90 | J37: 12/05/2025 | K37: 15 | L37: 450 | M37: 280 | N37: Taladro Radial TR-200 | O37: RESPONSABLE B | P37: Ing. Carlos Martínez López
A38: 28 | B38: 2 | C38: 15/05/2025 | D38: 09:00 | E38: =TRUE() -> TRUE | F38: RESPONSABLE B | G38: Inspección del sistema hidráulico, nivel de aceite y filtros de retorno | H38: =TRUE() -> TRUE | I38: 90 | J38: 15/05/2025 | K38: 7 | L38: 450 | M38: 320 | N38: Fresadora Vertical FV-300 | O38: RESPONSABLE B | P38: Ing. Carlos Martínez López
A39: 29 | B39: 4 | C39: 20/05/2025 | D39: 08:30 | E39: =TRUE() -> TRUE | F39: RESPONSABLE B | G39: Calibración de amperaje, voltaje de arco y parámetros de alimentación de alambre | H39: =TRUE() -> TRUE | I39: 120 | J39: 20/05/2025 | K39: 30 | L39: 600 | M39: 420 | N39: Soldadora MIG SW-450 | O39: RESPONSABLE B | P39: Ing. Carlos Martínez López
A40: 30 | B40: 8 | C40: 25/05/2025 | D40: 07:00 | E40: =FALSE() -> FALSE | F40: RESPONSABLE A | G40: CORRECTIVO: Desalineación severa de banda — corrección de rodillos y guía lateral | H40: =TRUE() -> TRUE | I40: 180 | J40: 25/05/2025 | K40: 0 | L40: 900 | M40: 650 | N40: Banda Transportadora BT-20 | O40: RESPONSABLE A | P40: Ing. Carlos Martínez López

Sheet PM
A1: REGISTRO DE INSUMOS Y REPUESTOS POR MANTENIMIENTO
A2: Cada fila = un material usado en un mantenimiento. Vinculado automáticamente con ALMACEN.
A3: ID MANT. | B3: FECHA | C3: COD. REPUESTO | D3: DESCRIPCIÓN | E3: CANTIDAD | F3: PRECIO UNIT. | G3: SUBTOTAL | H3: ESTADO INVENT.
A4: ▶ Ingrese manualmente o use el formulario. SUBTOTAL = Cantidad × Precio Unit. | Estado Inventario se actualiza al descontar de ALMACEN.
A5: 1 | B5: 08/01/2025 | C5: REP-001 | D5: Aceite de motor SAE 40 | E5: 2 | F5: 15 | G5: =E5*F5 -> 30 | H5: ✔ OK
A6: 1 | B6: 08/01/2025 | C6: REP-005 | D6: Grasa industrial Alvania | E6: 1 | F6: 12 | G6: =E6*F6 -> 12 | H6: ✔ OK
A7: 2 | B7: 10/01/2025 | C7: REP-007 | D7: Manguera hidráulica 1/2" | E7: 1 | F7: 22 | G7: =E7*F7 -> 22 | H7: ⚠ BAJO
A8: 2 | B8: 10/01/2025 | C8: REP-008 | D8: Sello mecánico bomba | E8: 1 | F8: 65 | G8: =E8*F8 -> 65 | H8: ✔ OK
A9: 3 | B9: 12/01/2025 | C9: REP-002 | D9: Filtro de aire industrial | E9: 1 | F9: 25 | G9: =E9*F9 -> 25 | H9: ✔ OK
A10: 3 | G10: =E10*F10 -> 0 | H10: ✔ OK
A11: 4 | B11: 15/01/2025 | C11: REP-006 | D11: Fusible 32A industrial | E11: 3 | F11: 2.5 | G11: =E11*F11 -> 7.5 | H11: ✔ OK
A12: 4 | B12: 15/01/2025 | C12: REP-009 | D12: Cable eléctrico THW 14AWG | E12: 5 | F12: 1.8 | G12: =E12*F12 -> 9 | H12: ✔ OK
A13: 5 | B13: 20/01/2025 | C13: REP-003 | D13: Rodamiento SKF 6205 | E13: 4 | F13: 45 | G13: =E13*F13 -> 180 | H13: ✔ OK
A14: 5 | B14: 20/01/2025 | C14: REP-010 | D14: Perno hexagonal M12x40 | E14: 8 | F14: 0.85 | G14: =E14*F14 -> 6.8 | H14: ✔ OK
A15: 6 | B15: 05/02/2025 | C15: REP-009 | D15: Cable eléctrico THW 14AWG | E15: 3 | F15: 1.8 | G15: =E15*F15 -> 5.4 | H15: ✔ OK
A16: 6 | B16: 05/02/2025 | C16: REP-006 | D16: Fusible 32A industrial | E16: 4 | F16: 2.5 | G16: =E16*F16 -> 10 | H16: ✔ OK
A17: 7 | B17: 07/02/2025 | C17: REP-008 | D17: Sello mecánico bomba | E17: 1 | F17: 65 | G17: =E17*F17 -> 65 | H17: ✔ OK
A18: 7 | B18: 07/02/2025 | C18: REP-007 | D18: Manguera hidráulica 1/2" | E18: 1 | F18: 22 | G18: =E18*F18 -> 22 | H18: ⚠ BAJO
A19: 8 | B19: 10/02/2025 | C19: REP-006 | D19: Fusible 32A industrial | E19: 6 | F19: 2.5 | G19: =E19*F19 -> 15 | H19: ✔ OK
A20: 8 | B20: 10/02/2025 | C20: REP-009 | D20: Cable eléctrico THW 14AWG | E20: 8 | F20: 1.8 | G20: =E20*F20 -> 14.4 | H20: ✔ OK
A21: 9 | B21: 14/02/2025 | C21: REP-010 | D21: Perno hexagonal M12x40 | E21: 10 | F21: 0.85 | G21: =E21*F21 -> 8.5 | H21: ✔ OK
A22: 10 | B22: 20/02/2025 | C22: REP-007 | D22: Manguera hidráulica 1/2" | E22: 4 | F22: 22 | G22: =E22*F22 -> 88 | H22: ⚠ BAJO
... A56: 30 | B56: 25/05/2025 | C56: REP-005 | D56: Grasa industrial Alvania | E56: 1 | F56: 12 | G56: =E56*F56 -> 12 | H56: ✔ OK
D57: TOTAL DE INSUMOS REGISTRADOS | G57: =SUM(G5:G56) -> 1762.25

Sheet AM
A1: ACTIVIDADES REALIZADAS POR MANTENIMIENTO
A2: Registre cada actividad ejecutada en cada intervención de mantenimiento.
A3: ID MANT. | B3: COD. ACTIVIDAD | C3: DESCRIPCIÓN DE LA ACTIVIDAD | D3: TIPO
A4: ▶ Una fila por actividad. El ID de Mantenimiento debe coincidir con la hoja MANTENIMIENTOS.
A5: 1 | B5: ACT-001 | C5: Revisión y cambio de aceite del motor | D5: Preventivo
A6: 1 | B6: ACT-007 | C6: Lubricación de partes móviles | D6: Preventivo
A7: 1 | B7: ACT-015 | C7: Prueba de funcionamiento y ajuste final | D7: Preventivo
A8: 2 | B8: ACT-002 | C8: Inspección del sistema hidráulico | D8: Preventivo
A9: 2 | B9: ACT-017 | C9: Reemplazo de sellos y empaques | D9: Preventivo
A10: 3 | B10: ACT-003 | C10: Limpieza de filtros y sistema de enfriamiento | D10: Preventivo
A11: 3 | B11: ACT-001 | C11: Revisión y cambio de aceite del motor | D11: Preventivo
A12: 4 | B12: ACT-009 | C12: Inspección de soldaduras y estructuras | D12: Preventivo
A13: 4 | B13: ACT-006 | C13: Inspección eléctrica general | D13: Preventivo
A14: 4 | B14: ACT-018 | C14: Verificación de torques y ajuste estructural | D14: Preventivo
A15: 5 | B15: ACT-011 | C15: Cambio de rodamientos | D15: Correctivo
A16: 5 | B16: ACT-014 | C16: Alineación y balanceo | D16: Correctivo
... A64: 30 | B64: ACT-015 | C64: Prueba de funcionamiento y ajuste final | D64: Correctivo

Sheet COSTOS
A1: ANÁLISIS Y CONTROL DE COSTOS DE MANTENIMIENTO
A2: Los datos se calculan automáticamente desde MANTENIMIENTOS y PM. Costos en moneda local (MXN).
A3: COSTO MO TOTAL | C3: COSTO INSUMOS TOTAL | E3: COSTO TOTAL MANTENIMIENTO | G3: MANTENIMIENTOS REGISTRADOS | I3: COSTO PROMEDIO POR EVENTO
A4: =SUM(MANTENIMIENTOS!L11:L5000) -> 19950 | C4: =SUM(MANTENIMIENTOS!M11:M5000) -> 22600 | E4: =SUM(MANTENIMIENTOS!L11:L5000)+SUM(MANTENIMIENTOS!M11:M5000) -> 42550 | G4: =COUNTA(MANTENIMIENTOS!A11:A5000) -> 30 | I4: =IFERROR((SUM(MANTENIMIENTOS!L11:L5000)+SUM(MANTENIMIENTOS!M11:M5000))/COUNTA(MANTENIMIENTOS!A11:A5000),0) -> 1418.3333
A7: CÓDIGO | B7: EQUIPO | C7: TIPO | D7: # MANTENIMIENTOS | E7: COSTO M.O. | F7: COSTO INSUMOS | G7: COSTO TOTAL | H7: % DEL TOTAL | I7: COSTO PROM/EVENTO | J7: CLASIFICACIÓN
A8: M-001 | B8: Torno CNC TL-500 | C8: Preventivo | D8: =COUNTIFS(MANTENIMIENTOS!N:N,B8,MANTENIMIENTOS!E:E,TRUE()) -> 4 | E8: =SUMIFS(MANTENIMIENTOS!L:L,MANTENIMIENTOS!N:N,B8,MANTENIMIENTOS!E:E,TRUE()) -> 2450 | F8: =SUMIFS(MANTENIMIENTOS!M:M,MANTENIMIENTOS!N:N,B8,MANTENIMIENTOS!E:E,TRUE()) -> 2360 | G8: =E8+F8 -> 4810 | H8: =IFERROR(G8/(SUM(MANTENIMIENTOS!L11:L5000)+SUM(MANTENIMIENTOS!M11:M5000)),0) -> 0.11304348 | I8: =IFERROR(G8/D8,0) -> 1202.5 | J8: =IF(G8=0,"Sin datos",IF(G8>10000,"💰 Alto",IF(G8>3000,"⚠ Moderado","✔ Bajo"))) -> ⚠ Moderado
A9: M-001 | B9: Torno CNC TL-500 | C9: Correctivo | D9: =COUNTIFS(MANTENIMIENTOS!N:N,B9,MANTENIMIENTOS!E:E,FALSE()) -> 0 | E9: =SUMIFS(MANTENIMIENTOS!L:L,MANTENIMIENTOS!N:N,B9,MANTENIMIENTOS!E:E,FALSE()) -> 0 | F9: =SUMIFS(MANTENIMIENTOS!M:M,MANTENIMIENTOS!N:N,B9,MANTENIMIENTOS!E:E,FALSE()) -> 0 | G9: =E9+F9 -> 0 | H9: =IFERROR(G9/(SUM(MANTENIMIENTOS!L11:L5000)+SUM(MANTENIMIENTOS!M11:M5000)),0) -> 0 | I9: =IFERROR(G9/D9,0) -> 0 | J9: =IF(G9=0,"Sin datos",IF(G9>10000,"💰 Alto",IF(G9>3000,"⚠ Moderado","✔ Bajo"))) -> Sin datos
A10: M-002 | B10: Fresadora Vertical FV-300 | C10: Preventivo | D10: =COUNTIFS(MANTENIMIENTOS!N:N,B10,MANTENIMIENTOS!E:E,TRUE()) -> 3 | E10: =SUMIFS(MANTENIMIENTOS!L:L,MANTENIMIENTOS!N:N,B10,MANTENIMIENTOS!E:E,TRUE()) -> 1200 | F10: =SUMIFS(MANTENIMIENTOS!M:M,MANTENIMIENTOS!N:N,B10,MANTENIMIENTOS!E:E,TRUE()) -> 790 | G10: =E10+F10 -> 1990 | H10: =IFERROR(G10/(SUM(MANTENIMIENTOS!L11:L5000)+SUM(MANTENIMIENTOS!M11:M5000)),0) -> 0.046768508 | I10: =IFERROR(G10/D10,0) -> 663.33333 | J10: =IF(G10=0,"Sin datos",IF(G10>10000,"💰 Alto",IF(G10>3000,"⚠ Moderado","✔ Bajo"))) -> ✔ Bajo
A11: M-002 | B11: Fresadora Vertical FV-300 | C11: Correctivo | D11: =COUNTIFS(MANTENIMIENTOS!N:N,B11,MANTENIMIENTOS!E:E,FALSE()) -> 1 | E11: =SUMIFS(MANTENIMIENTOS!L:L,MANTENIMIENTOS!N:N,B11,MANTENIMIENTOS!E:E,FALSE()) -> 1500 | F11: =SUMIFS(MANTENIMIENTOS!M:M,MANTENIMIENTOS!N:N,B11,MANTENIMIENTOS!E:E,FALSE()) -> 3200 | G11: =E11+F11 -> 4700 | H11: =IFERROR(G11/(SUM(MANTENIMIENTOS!L11:L5000)+SUM(MANTENIMIENTOS!M11:M5000)),0) -> 0.11045828 | I11: =IFERROR(G11/D11,0) -> 4700 | J11: =IF(G11=0,"Sin datos",IF(G11>10000,"💰 Alto",IF(G11>3000,"⚠ Moderado","✔ Bajo"))) -> ⚠ Moderado
A12: M-003 | B12: Taladro Radial TR-200 | C12: Preventivo | D12: =COUNTIFS(MANTENIMIENTOS!N:N,B12,MANTENIMIENTOS!E:E,TRUE()) -> 2 | E12: =SUMIFS(MANTENIMIENTOS!L:L,MANTENIMIENTOS!N:N,B12,MANTENIMIENTOS!E:E,TRUE()) -> 750 | F12: =SUMIFS(MANTENIMIENTOS!M:M,MANTENIMIENTOS!N:N,B12,MANTENIMIENTOS!E:E,TRUE()) -> 460 | G12: =E12+F12 -> 1210 | H12: =IFERROR(G12/(SUM(MANTENIMIENTOS!L11:L5000)+SUM(MANTENIMIENTOS!M11:M5000)),0) -> 0.028437133 | I12: =IFERROR(G12/D12,0) -> 605 | J12: =IF(G12=0,"Sin datos",IF(G12>10000,"💰 Alto",IF(G12>3000,"⚠ Moderado","✔ Bajo"))) -> ✔ Bajo
A13: M-004 | B13: Soldadora MIG SW-450 | C13: Preventivo | D13: =COUNTIFS(MANTENIMIENTOS!N:N,B13,MANTENIMIENTOS!E:E,TRUE()) -> 2 | E13: =SUMIFS(MANTENIMIENTOS!L:L,MANTENIMIENTOS!N:N,B13,MANTENIMIENTOS!E:E,TRUE()) -> 1050 | F13: =SUMIFS(MANTENIMIENTOS!M:M,MANTENIMIENTOS!N:N,B13,MANTENIMIENTOS!E:E,TRUE()) -> 670 | G13: =E13+F13 -> 1720 | H13: =IFERROR(G13/(SUM(MANTENIMIENTOS!L11:L5000)+SUM(MANTENIMIENTOS!M11:M5000)),0) -> 0.040423032 | I13: =IFERROR(G13/D13,0) -> 860 | J13: =IF(G13=0,"Sin datos",IF(G13>10000,"💰 Alto",IF(G13>3000,"⚠ Moderado","✔ Bajo"))) -> ✔ Bajo
A14: M-004 | B14: Soldadora MIG SW-450 | C14: Correctivo | D14: =COUNTIFS(MANTENIMIENTOS!N:N,B14,MANTENIMIENTOS!E:E,FALSE()) -> 1 | E14: =SUMIFS(MANTENIMIENTOS!L:L,MANTENIMIENTOS!N:N,B14,MANTENIMIENTOS!E:E,FALSE()) -> 1200 | F14: =SUMIFS(MANTENIMIENTOS!M:M,MANTENIMIENTOS!N:N,B14,MANTENIMIENTOS!E:E,FALSE()) -> 1800 | G14: =E14+F14 -> 3000 | H14: =IFERROR(G14/(SUM(MANTENIMIENTOS!L11:L5000)+SUM(MANTENIMIENTOS!M11:M5000)),0) -> 0.070505288 | I14: =IFERROR(G14/D14,0) -> 3000 | J14: =IF(G14=0,"Sin datos",IF(G14>10000,"💰 Alto",IF(G14>3000,"⚠ Moderado","✔ Bajo"))) -> ✔ Bajo
A15: M-005 | B15: Compresor Industrial CI-75 | C15: Preventivo | D15: =COUNTIFS(MANTENIMIENTOS!N:N,B15,MANTENIMIENTOS!E:E,TRUE()) -> 3 | E15: =SUMIFS(MANTENIMIENTOS!L:L,MANTENIMIENTOS!N:N,B15,MANTENIMIENTOS!E:E,TRUE()) -> 1450 | F15: =SUMIFS(MANTENIMIENTOS!M:M,MANTENIMIENTOS!N:N,B15,MANTENIMIENTOS!E:E,TRUE()) -> 1010 | G15: =E15+F15 -> 2460 | H15: =IFERROR(G15/(SUM(MANTENIMIENTOS!L11:L5000)+SUM(MANTENIMIENTOS!M11:M5000)),0) -> 0.057814336 | I15: =IFERROR(G15/D15,0) -> 820 | J15: =IF(G15=0,"Sin datos",IF(G15>10000,"💰 Alto",IF(G15>3000,"⚠ Moderado","✔ Bajo"))) -> ✔ Bajo
A16: M-006 | B16: Prensa Hidráulica PH-100 | C16: Preventivo | D16: =COUNTIFS(MANTENIMIENTOS!N:N,B16,MANTENIMIENTOS!E:E,TRUE()) -> 3 | E16: =SUMIFS(MANTENIMIENTOS!L:L,MANTENIMIENTOS!N:N,B16,MANTENIMIENTOS!E:E,TRUE()) -> 1650 | F16: =SUMIFS(MANTENIMIENTOS!M:M,MANTENIMIENTOS!N:N,B16,MANTENIMIENTOS!E:E,TRUE()) -> 1540 | G16: =E16+F16 -> 3190 | H16: =IFERROR(G16/(SUM(MANTENIMIENTOS!L11:L5000)+SUM(MANTENIMIENTOS!M11:M5000)),0) -> 0.074970623 | I16: =IFERROR(G16/D16,0) -> 1063.3333 | J16: =IF(G16=0,"Sin datos",IF(G16>10000,"💰 Alto",IF(G16>3000,"⚠ Moderado","✔ Bajo"))) -> ⚠ Moderado
A17: M-007 | B17: Grúa Puente GP-5T | C17: Preventivo | D17: =COUNTIFS(MANTENIMIENTOS!N:N,B17,MANTENIMIENTOS!E:E,TRUE()) -> 2 | E17: =SUMIFS(MANTENIMIENTOS!L:L,MANTENIMIENTOS!N:N,B17,MANTENIMIENTOS!E:E,TRUE()) -> 1350 | F17: =SUMIFS(MANTENIMIENTOS!M:M,MANTENIMIENTOS!N:N,B17,MANTENIMIENTOS!E:E,TRUE()) -> 800 | G17: =E17+F17 -> 2150 | H17: =IFERROR(G17/(SUM(MANTENIMIENTOS!L11:L5000)+SUM(MANTENIMIENTOS!M11:M5000)),0) -> 0.05052879 | I17: =IFERROR(G17/D17,0) -> 1075 | J17: =IF(G17=0,"Sin datos",IF(G17>10000,"💰 Alto",IF(G17>3000,"⚠ Moderado","✔ Bajo"))) -> ✔ Bajo
A18: M-007 | B18: Grúa Puente GP-5T | C18: Correctivo | D18: =COUNTIFS(MANTENIMIENTOS!N:N,B18,MANTENIMIENTOS!E:E,FALSE()) -> 1 | E18: =SUMIFS(MANTENIMIENTOS!L:L,MANTENIMIENTOS!N:N,B18,MANTENIMIENTOS!E:E,FALSE()) -> 1800 | F18: =SUMIFS(MANTENIMIENTOS!M:M,MANTENIMIENTOS!N:N,B18,MANTENIMIENTOS!E:E,FALSE()) -> 3800 | G18: =E18+F18 -> 5600 | H18: =IFERROR(G18/(SUM(MANTENIMIENTOS!L11:L5000)+SUM(MANTENIMIENTOS!M11:M5000)),0) -> 0.13160987 | I18: =IFERROR(G18/D18,0) -> 5600 | J18: =IF(G18=0,"Sin datos",IF(G18>10000,"💰 Alto",IF(G18>3000,"⚠ Moderado","✔ Bajo"))) -> ⚠ Moderado
A19: M-008 | B19: Banda Transportadora BT-20 | C19: Preventivo | D19: =COUNTIFS(MANTENIMIENTOS!N:N,B19,MANTENIMIENTOS!E:E,TRUE()) -> 2 | E19: =SUMIFS(MANTENIMIENTOS!L:L,MANTENIMIENTOS!N:N,B19,MANTENIMIENTOS!E:E,TRUE()) -> 750 | F19: =SUMIFS(MANTENIMIENTOS!M:M,MANTENIMIENTOS!N:N,B19,MANTENIMIENTOS!E:E,TRUE()) -> 530 | G19: =E19+F19 -> 1280 | H19: =IFERROR(G19/(SUM(MANTENIMIENTOS!L11:L5000)+SUM(MANTENIMIENTOS!M11:M5000)),0) -> 0.030082256 | I19: =IFERROR(G19/D19,0) -> 640 | J19: =IF(G19=0,"Sin datos",IF(G19>10000,"💰 Alto",IF(G19>3000,"⚠ Moderado","✔ Bajo"))) -> ✔ Bajo
A20: M-009 | B20: Generador Eléctrico GE-150 | C20: Preventivo | D20: =COUNTIFS(MANTENIMIENTOS!N:N,B20,MANTENIMIENTOS!E:E,TRUE()) -> 2 | E20: =SUMIFS(MANTENIMIENTOS!L:L,MANTENIMIENTOS!N:N,B20,MANTENIMIENTOS!E:E,TRUE()) -> 1350 | F20: =SUMIFS(MANTENIMIENTOS!M:M,MANTENIMIENTOS!N:N,B20,MANTENIMIENTOS!E:E,TRUE()) -> 1270 | G20: =E20+F20 -> 2620 | H20: =IFERROR(G20/(SUM(MANTENIMIENTOS!L11:L5000)+SUM(MANTENIMIENTOS!M11:M5000)),0) -> 0.061574618 | I20: =IFERROR(G20/D20,0) -> 1310 | J20: =IF(G20=0,"Sin datos",IF(G20>10000,"💰 Alto",IF(G20>3000,"⚠ Moderado","✔ Bajo"))) -> ✔ Bajo
A21: M-010 | B21: Bomba Centrífuga BC-50 | C21: Preventivo | D21: =COUNTIFS(MANTENIMIENTOS!N:N,B21,MANTENIMIENTOS!E:E,TRUE()) -> 1 | E21: =SUMIFS(MANTENIMIENTOS!L:L,MANTENIMIENTOS!N:N,B21,MANTENIMIENTOS!E:E,TRUE()) -> 450 | F21: =SUMIFS(MANTENIMIENTOS!M:M,MANTENIMIENTOS!N:N,B21,MANTENIMIENTOS!E:E,TRUE()) -> 320 | G21: =E21+F21 -> 770 | H21: =IFERROR(G21/(SUM(MANTENIMIENTOS!L11:L5000)+SUM(MANTENIMIENTOS!M11:M5000)),0) -> 0.018096357 | I21: =IFERROR(G21/D21,0) -> 770 | J21: =IF(G21=0,"Sin datos",IF(G21>10000,"💰 Alto",IF(G21>3000,"⚠ Moderado","✔ Bajo"))) -> ✔ Bajo
A22: TOTALES | E22: =SUM(E8:E21) -> 16950 | F22: =SUM(F8:F21) -> 18550 | G22: =SUM(G8:G21) -> 35500 | H22: =SUM(MANTENIMIENTOS!L11:L5000)+SUM(MANTENIMIENTOS!M11:M5000) -> 42550 | I22: =SUM(I8:I21) -> 22309.167
A24: ANÁLISIS DE TIEMPO EN MANTENIMIENTO CORRECTIVO — 2025
A25: Base: 2,080 horas anuales de operación total | % = Horas correctivo ÷ 2,080 hrs
A26: HORAS ANUALES OPERACIÓN | C26: TOTAL MIN CORRECTIVO | E26: TOTAL HRS CORRECTIVO | G26: % TIEMPO EN CORRECTIVO | I26: CORRECTIVOS EJECUTADOS
A27: 2080 | C27: 1260 | E27: 21 | G27: 0.0101 | I27: 6
A28: CÓD. EQUIPO | B28: NOMBRE DEL EQUIPO | C28: TIEMPO CM (minutos) | D28: TIEMPO CM (horas) | E28: % DEL TOTAL 2,080 HRS | F28: # CORRECTIVOS EJECUTADOS | G28: COSTO TOTAL CORRECTIVO ($) | H28: COSTO POR HORA ($) | I28: CLASIFICACIÓN
A29: M-001 | B29: Torno CNC TL-500 | C29: — | D29: — | E29: — | F29: — | G29: — | H29: — | I29: ✅ Sin paro
A30: M-002 | B30: Fresadora Vertical FV-300 | C30: 300 | D30: 5 | E30: 0.0024038462 | F30: 1 | G30: 4700 | H30: 940 | I30: 🔶 Alto
A31: M-003 | B31: Taladro Radial TR-200 | C31: 240 | D31: 4 | E31: 0.0019230769 | F31: 1 | G31: 3300 | H31: 825 | I31: 🔶 Alto
A32: M-004 | B32: Soldadora MIG SW-450 | C32: 240 | D32: 4 | E32: 0.0019230769 | F32: 1 | G32: 3000 | H32: 750 | I32: 🔶 Alto
A33: M-005 | B33: Compresor Industrial CI-75 | C33: — | D33: — | E33: — | F33: — | G33: — | H33: — | I33: ✅ Sin paro
A34: M-006 | B34: Prensa Hidráulica PH-100 | C34: — | D34: — | E34: — | F34: — | G34: — | H34: — | I34: ✅ Sin paro
A35: M-007 | B35: Grúa Puente GP-5T | C35: 360 | D35: 6 | E35: 0.0028846154 | F35: 1 | G35: 5600 | H35: 933.33 | I35: 🔴 Crítico
A36: M-008 | B36: Banda Transportadora BT-20 | C36: 180 | D36: 3 | E36: 0.0014423077 | F36: 1 | G36: 1550 | H36: 516.67 | I36: ⚠ Moderado
A37: M-009 | B37: Generador Eléctrico GE-150 | C37: — | D37: — | E37: — | F37: — | G37: — | H37: — | I37: ✅ Sin paro
A38: M-010 | B38: Bomba Centrífuga BC-50 | C38: 180 | D38: 3 | E38: 0.0014423077 | F38: 1 | G38: 2200 | H38: 733.33 | I38: ⚠ Moderado
A39: TOTAL PLANTA | C39: 1260 | D39: 21 | E39: 0.0101 | F39: 6 | G39: 20350 | H39: 969.05 | I39: 1.01% del tiempo total de operación
A41: LEYENDA: | B41: ✅ Sin paro | C41: ⚠ Moderado | D41: 🔶 Alto | E41: 🔴 Crítico | F41: Referencia clase mundial: ≤ 5% tiempo en correctivo. Planta actual: 1.01% ✅

Sheet COTIZACION
A1: COTIZACIÓN DE MANTENIMIENTO
A6: N° COTIZACIÓN: | D6: COT-2025-001 | F6: FECHA: | H6: =TODAY() -> 46162
A7: DATOS DEL PROVEEDOR | F7: DATOS DEL CLIENTE
A8: Empresa: | B8: =CONFIG!B2 -> Industrias Metálicas del Centro S.A. de C.V. | F8: Razón Social: | G8: Industrias Metálicas del Centro S.A. de C.V.
A9: Dirección: | B9: Calle, Col., Ciudad | F9: Dirección: | G9: Blvd. Norte 2280, Parque Industrial Puebla 2000
A10: Tel: | B10: 55-0000-0000 | F10: Contacto: | G10: Ing. Roberto Sánchez — Gerencia de Planta
A11: Correo: | B11: correo@empresa.com | F11: Tel: | G11: 222 234-5678
A14: EQUIPO: | C14: Torno CNC TL-500 | F14: TIPO MANTENIMIENTO: | H14: Preventivo
A15: CÓDIGO: | C15: M-001 | F15: VIGENCIA COTIZ.: | H15: =TODAY()+30 -> 46192
A17: N° | B17: DESCRIPCIÓN DE LA ACTIVIDAD / CONCEPTO | C17: TIPO | D17: TIEMPO (hrs) | E17: COSTO UNIT. | F17: CANTIDAD | G17: SUBTOTAL | H17: IVA 16% | I17: TOTAL
A18: 1 | B18: M.O.: Cambio de aceite SAE 40 y limpieza de componentes internos | C18: Preventivo | D18: 2 | E18: 350 | F18: 2 | G18: =IFERROR(E18*F18,0) -> 700 | H18: =G18*0.16 -> 112 | I18: =G18+H18 -> 812
A19: 2 | B19: M.O.: Inspección eléctrica general y ajuste de tablero CNC | C19: Preventivo | D19: 1.5 | E19: 400 | F19: 1.5 | G19: =IFERROR(E19*F19,0) -> 600 | H19: =G19*0.16 -> 96 | I19: =G19+H19 -> 696
A20: 3 | B20: M.O.: Lubricación de guías lineales, carros y sistema de avance | C20: Preventivo | D20: 1 | E20: 300 | F20: 1 | G20: =IFERROR(E20*F20,0) -> 300 | H20: =G20*0.16 -> 48 | I20: =G20+H20 -> 348
A21: 4 | B21: M.O.: Calibración de parámetros, compensaciones y ciclo de prueba CNC | C21: Preventivo | D21: 3 | E21: 450 | F21: 3 | G21: =IFERROR(E21*F21,0) -> 1350 | H21: =G21*0.16 -> 216 | I21: =G21+H21 -> 1566
A22: 5 | B22: M.O.: Revisión de carro principal, torreta y sujeción de herramienta | C22: Preventivo | D22: 1 | E22: 300 | F22: 1 | G22: =IFERROR(E22*F22,0) -> 300 | H22: =G22*0.16 -> 48 | I22: =G22+H22 -> 348
A23: 6 | B23: Material: Aceite de motor SAE 40 — 2 litros | C23: Material | E23: 15 | F23: 2 | G23: =IFERROR(E23*F23,0) -> 30 | H23: =G23*0.16 -> 4.8 | I23: =G23+H23 -> 34.8
A24: 7 | B24: Material: Filtro de aceite industrial | C24: Material | E24: 35 | F24: 1 | G24: =IFERROR(E24*F24,0) -> 35 | H24: =G24*0.16 -> 5.6 | I24: =G24+H24 -> 40.6
A25: 8 | B25: Material: Grasa para guías Alvania — 500 g | C25: Material | E25: 12 | F25: 1 | G25: =IFERROR(E25*F25,0) -> 12 | H25: =G25*0.16 -> 1.92 | I25: =G25+H25 -> 13.92
A26: 9 | B26: Material: Fusibles industriales 32A — juego de 4 piezas | C26: Material | E26: 2.5 | F26: 4 | G26: =IFERROR(E26*F26,0) -> 10 | H26: =G26*0.16 -> 1.6 | I26: =G26+H26 -> 11.6
A27: 10 | B27: M.O.: Verificación final, prueba de ciclo y reporte técnico escrito | C27: Preventivo | D27: 1 | E27: 350 | F27: 1 | G27: =IFERROR(E27*F27,0) -> 350 | H27: =G27*0.16 -> 56 | I27: =G27+H27 -> 406
E28: SUBTOTAL: | G28: =SUM(G18:G27) -> 3687
E29: IVA (16%): | H29: =SUM(H18:H27) -> 589.92
E30: TOTAL COTIZACIÓN: | I30: =SUM(I18:I27) -> 4276.92
A33: NOTAS Y CONDICIONES:
A34: 1. Esta cotización es válida por 30 días a partir de la fecha de emisión.
A35: Ing. Carlos Martínez López
A36: Jefe de Mantenimiento
A37: 4. Se requiere orden de compra o contrato firmado para inicio de trabajos.
A40: ____________________________________ | F40: ____________________________________
A41: ELABORÓ | F41: AUTORIZÓ

Sheet INFORME
A1: INFORME INDIVIDUAL DE INDICADORES POR EQUIPO
A2: Ingrese el Código del Equipo en la celda amarilla para filtrar su informe.
A4: ▶ Código de Equipo: | D4: M-001
A5: =IFERROR(VLOOKUP(D4,tabla_maquinas,3,FALSE()),"Equipo no encontrado") -> Equipo no encontrado
A7: PROGRAMADOS | D7: EJECUTADOS | G7: REPROGRAMADOS | J7: NO EJECUTADOS
A8: =COUNTIF(PROGRAMA!B10:B5000,D4) -> 4 | D8: =SUMIF(PROGRAMA!B10:B5000,D4,PROGRAMA!I10:I5000) -> 4 | G8: =SUMIF(PROGRAMA!B10:B5000,D4,PROGRAMA!J10:J5000) -> 0 | J8: =SUMIF(PROGRAMA!B10:B5000,D4,PROGRAMA!K10:K5000) -> 0
A11: % CUMPLIMIENTO | D11: % EFECTIVIDAD | G11: SEMÁFORO | J11: COSTO TOTAL
A12: =IFERROR(SUMIF(PROGRAMA!B10:B5000,D4,PROGRAMA!I10:I5000)/COUNTIF(PROGRAMA!B10:B5000,D4),0) -> 1 | D12: =IFERROR((SUMIF(PROGRAMA!B10:B5000,D4,PROGRAMA!I10:I5000)+SUMIF(PROGRAMA!B10:B5000,D4,PROGRAMA!J10:J5000))/(COUNTIF(PROGRAMA!B10:B5000,D4)-SUMIF(PROGRAMA!B10:B5000,D4,PROGRAMA!K10:K5000)),0) -> 1 | G12: =IF(A12>=0.9,"✅ ÓPTIMO",IF(A12>=0.75,"⚠ REGULAR","❌ CRÍTICO")) -> ✅ ÓPTIMO | J12: =SUMIFS(MANTENIMIENTOS!L:L,MANTENIMIENTOS!N:N,IFERROR(VLOOKUP(D4,tabla_maquinas,3,FALSE()),"X"))+SUMIFS(MANTENIMIENTOS!M:M,MANTENIMIENTOS!N:N,IFERROR(VLOOKUP(D4,tabla_maquinas,3,FALSE()),"X")) -> 0
A16: DETALLE DE ACTIVIDADES DEL EQUIPO
A17: N° | B17: ACTIVIDAD | C17: DÍA INICIO | D17: FREC. | E17: TIPO FREC. | F17: ESTADO | G17: CUMPLIM. | H17: EFECTIVID. | I17: PRÓX. MTTO. | J17: DÍAS FALT. | K17: OBSERV. | L17: —
A18: 1 | B18: =IFERROR(INDEX(PROGRAMA!D$10:D$5000,MATCH(1,(PROGRAMA!B$10:B$5000=$D$4)*(ROW(PROGRAMA!D$10:D$5000)-ROW(PROGRAMA!D$10)+1=1),0)),"—") -> —
A19: 2 | B19: =IFERROR(INDEX(PROGRAMA!D$10:D$5000,MATCH(1,(PROGRAMA!B$10:B$5000=$D$4)*(ROW(PROGRAMA!D$10:D$5000)-ROW(PROGRAMA!D$10)+1=2),0)),"—") -> —
A20: 3 | B20: =IFERROR(INDEX(PROGRAMA!D$10:D$5000,MATCH(1,(PROGRAMA!B$10:B$5000=$D$4)*(ROW(PROGRAMA!D$10:D$5000)-ROW(PROGRAMA!D$10)+1=3),0)),"—") -> —
A21: 4 | B21: =IFERROR(INDEX(PROGRAMA!D$10:D$5000,MATCH(1,(PROGRAMA!B$10:B$5000=$D$4)*(ROW(PROGRAMA!D$10:D$5000)-ROW(PROGRAMA!D$10)+1=4),0)),"—") -> —
A22: 5 | B22: =IFERROR(INDEX(PROGRAMA!D$10:D$5000,MATCH(1,(PROGRAMA!B$10:B$5000=$D$4)*(ROW(PROGRAMA!D$10:D$5000)-ROW(PROGRAMA!D$10)+1=5),0)),"—") -> —
A23: 6 | B23: =IFERROR(INDEX(PROGRAMA!D$10:D$5000,MATCH(1,(PROGRAMA!B$10:B$5000=$D$4)*(ROW(PROGRAMA!D$10:D$5000)-ROW(PROGRAMA!D$10)+1=6),0)),"—") -> —
A24: 7 | B24: =IFERROR(INDEX(PROGRAMA!D$10:D$5000,MATCH(1,(PROGRAMA!B$10:B$5000=$D$4)*(ROW(PROGRAMA!D$10:D$5000)-ROW(PROGRAMA!D$10)+1=7),0)),"—") -> —
A25: 8 | B25: =IFERROR(INDEX(PROGRAMA!D$10:D$5000,MATCH(1,(PROGRAMA!B$10:B$5000=$D$4)*(ROW(PROGRAMA!D$10:D$5000)-ROW(PROGRAMA!D$10)+1=8),0)),"—") -> —
A26: 9 | B26: =IFERROR(INDEX(PROGRAMA!D$10:D$5000,MATCH(1,(PROGRAMA!B$10:B$5000=$D$4)*(ROW(PROGRAMA!D$10:D$5000)-ROW(PROGRAMA!D$10)+1=9),0)),"—") -> —
A27: 10 | B27: =IFERROR(INDEX(PROGRAMA!D$10:D$5000,MATCH(1,(PROGRAMA!B$10:B$5000=$D$4)*(ROW(PROGRAMA!D$10:D$5000)-ROW(PROGRAMA!D$10)+1=10),0)),"—") -> —
A28: 11 | B28: =IFERROR(INDEX(PROGRAMA!D$10:D$5000,MATCH(1,(PROGRAMA!B$10:B$5000=$D$4)*(ROW(PROGRAMA!D$10:D$5000)-ROW(PROGRAMA!D$10)+1=11),0)),"—") -> —
A29: 12 | B29: =IFERROR(INDEX(PROGRAMA!D$10:D$5000,MATCH(1,(PROGRAMA!B$10:B$5000=$D$4)*(ROW(PROGRAMA!D$10:D$5000)-ROW(PROGRAMA!D$10)+1=12),0)),"—") -> —
A30: 13 | B30: =IFERROR(INDEX(PROGRAMA!D$10:D$5000,MATCH(1,(PROGRAMA!B$10:B$5000=$D$4)*(ROW(PROGRAMA!D$10:D$5000)-ROW(PROGRAMA!D$10)+1=13),0)),"—") -> —
A31: 14 | B31: =IFERROR(INDEX(PROGRAMA!D$10:D$5000,MATCH(1,(PROGRAMA!B$10:B$5000=$D$4)*(ROW(PROGRAMA!D$10:D$5000)-ROW(PROGRAMA!D$10)+1=14),0)),"—") -> —
A32: 15 | B32: =IFERROR(INDEX(PROGRAMA!D$10:D$5000,MATCH(1,(PROGRAMA!B$10:B$5000=$D$4)*(ROW(PROGRAMA!D$10:D$5000)-ROW(PROGRAMA!D$10)+1=15),0)),"—") -> —

Sheet BD
A1: BASE DE DATOS — CATÁLOGOS DEL SISTEMA
A2: ACTIVIDADES DE MANTENIMIENTO | F2: RESPONSABLES Y ÁREAS | J2: MODOS DE FALLO
A3: N° | B3: CÓDIGO | C3: DESCRIPCIÓN DE ACTIVIDAD | D3: TIPO | F3: ID | G3: RESPONSABLE | H3: ÁREA | J3: CÓDIGO | K3: DESCRIPCIÓN
A4: 1 | B4: ACT-001 | C4: Revisión y cambio de aceite del motor | D4: Preventivo | F4: 1 | G4: RESPONSABLE A | H4: Taller A | J4: FCM-01 | K4: Fallos Componentes Mecánicos
A5: 2 | B5: ACT-002 | C5: Inspección del sistema hidráulico | D5: Preventivo | F5: 2 | G5: RESPONSABLE B | H5: Taller B | J5: FCM-02 | K5: Fallos Componentes Hidráulicos
